{
 "cells": [
  {
   "cell_type": "code",
   "execution_count": 1,
   "id": "9790460a",
   "metadata": {},
   "outputs": [],
   "source": [
    "import os\n",
    "import numpy as np\n",
    "import shutil\n",
    "num_classes = 2\n",
    "CHANNELS = 3\n",
    "IMAGE_RESIZE = 224\n",
    "RESNET50_POOLING_AVERAGE = 'avg'\n",
    "DENSE_LAYER_ACTIVATION = 'softmax'\n",
    "OBJECTIVE_FUNCTION = 'categorical_crossentropy'\n",
    "LOSS_METRICS = ['accuracy']\n",
    "\n",
    "# EARLY_STOP_PATIENCE must be < NUM_EPOCHS\n",
    "\n",
    "NUM_EPOCHS = 10\n",
    "\n",
    "EARLY_STOP_PATIENCE = 3\n",
    "# These steps value should be proper FACTOR of no.-of-images in train & valid folders respectively\n",
    "\n",
    "# Training images processed in each step would be no.-of-train-images / STEPS_PER_EPOCH_TRAINING\n",
    "\n",
    "STEPS_PER_EPOCH_TRAINING = 10\n",
    "\n",
    "STEPS_PER_EPOCH_VALIDATION = 10\n",
    "\n",
    "# These steps value should be proper FACTOR of no.-of-images in train & valid folders respectively\n",
    "\n",
    "# NOTE that these BATCH* are for Keras ImageDataGenerator batching to fill epoch step input\n",
    "\n",
    "BATCH_SIZE_TRAINING = 100\n",
    "\n",
    "BATCH_SIZE_VALIDATION = 100\n",
    "\n",
    "# Using 1 to easily manage mapping between test_generator & prediction for submission preparation\n",
    "\n",
    "BATCH_SIZE_TESTING = 1"
   ]
  },
  {
   "cell_type": "markdown",
   "id": "983ba9e4",
   "metadata": {},
   "source": [
    "#### Defining the model"
   ]
  },
  {
   "cell_type": "code",
   "execution_count": null,
   "id": "e03c4131",
   "metadata": {},
   "outputs": [],
   "source": []
  },
  {
   "cell_type": "code",
   "execution_count": 2,
   "id": "1d0e1869",
   "metadata": {},
   "outputs": [
    {
     "ename": "AttributeError",
     "evalue": "'Sequential' object has no attribute '_nested_outputs'",
     "output_type": "error",
     "traceback": [
      "\u001b[1;31m---------------------------------------------------------------------------\u001b[0m",
      "\u001b[1;31mAttributeError\u001b[0m                            Traceback (most recent call last)",
      "\u001b[1;32m~\\AppData\\Local\\Temp/ipykernel_15820/4185283976.py\u001b[0m in \u001b[0;36m<module>\u001b[1;34m\u001b[0m\n\u001b[0;32m     22\u001b[0m \u001b[1;32mfrom\u001b[0m \u001b[0mtensorflow\u001b[0m\u001b[1;33m.\u001b[0m\u001b[0mkeras\u001b[0m\u001b[1;33m.\u001b[0m\u001b[0moptimizers\u001b[0m \u001b[1;32mimport\u001b[0m \u001b[0mSGD\u001b[0m\u001b[1;33m\u001b[0m\u001b[1;33m\u001b[0m\u001b[0m\n\u001b[0;32m     23\u001b[0m \u001b[1;33m\u001b[0m\u001b[0m\n\u001b[1;32m---> 24\u001b[1;33m \u001b[0mx\u001b[0m \u001b[1;33m=\u001b[0m \u001b[0mlayers\u001b[0m\u001b[1;33m.\u001b[0m\u001b[0mDropout\u001b[0m\u001b[1;33m(\u001b[0m\u001b[1;36m0.5\u001b[0m\u001b[1;33m)\u001b[0m\u001b[1;33m(\u001b[0m\u001b[0mmy_new_model\u001b[0m\u001b[1;33m.\u001b[0m\u001b[0moutput\u001b[0m\u001b[1;33m)\u001b[0m\u001b[1;33m\u001b[0m\u001b[1;33m\u001b[0m\u001b[0m\n\u001b[0m\u001b[0;32m     25\u001b[0m \u001b[1;33m\u001b[0m\u001b[0m\n\u001b[0;32m     26\u001b[0m \u001b[0mx\u001b[0m \u001b[1;33m=\u001b[0m \u001b[0mlayers\u001b[0m\u001b[1;33m.\u001b[0m\u001b[0mFlatten\u001b[0m\u001b[1;33m(\u001b[0m\u001b[1;33m)\u001b[0m\u001b[1;33m(\u001b[0m\u001b[0mx\u001b[0m\u001b[1;33m)\u001b[0m\u001b[1;33m\u001b[0m\u001b[1;33m\u001b[0m\u001b[0m\n",
      "\u001b[1;32m~\\anaconda3\\lib\\site-packages\\tensorflow\\python\\keras\\engine\\functional.py\u001b[0m in \u001b[0;36moutput\u001b[1;34m(self)\u001b[0m\n\u001b[0;32m    301\u001b[0m       \u001b[0mRuntimeError\u001b[0m\u001b[1;33m:\u001b[0m \u001b[1;32mif\u001b[0m \u001b[0mcalled\u001b[0m \u001b[1;32min\u001b[0m \u001b[0mEager\u001b[0m \u001b[0mmode\u001b[0m\u001b[1;33m.\u001b[0m\u001b[1;33m\u001b[0m\u001b[1;33m\u001b[0m\u001b[0m\n\u001b[0;32m    302\u001b[0m     \"\"\"\n\u001b[1;32m--> 303\u001b[1;33m     \u001b[1;32mreturn\u001b[0m \u001b[0mself\u001b[0m\u001b[1;33m.\u001b[0m\u001b[0m_nested_outputs\u001b[0m\u001b[1;33m\u001b[0m\u001b[1;33m\u001b[0m\u001b[0m\n\u001b[0m\u001b[0;32m    304\u001b[0m \u001b[1;33m\u001b[0m\u001b[0m\n\u001b[0;32m    305\u001b[0m   \u001b[1;33m@\u001b[0m\u001b[0mproperty\u001b[0m\u001b[1;33m\u001b[0m\u001b[1;33m\u001b[0m\u001b[0m\n",
      "\u001b[1;31mAttributeError\u001b[0m: 'Sequential' object has no attribute '_nested_outputs'"
     ]
    }
   ],
   "source": [
    "import keras\n",
    "\n",
    "from tensorflow.keras.applications.resnet50 import ResNet50\n",
    "\n",
    "from tensorflow.python.keras.models import Sequential\n",
    "\n",
    "from tensorflow.python.keras.layers import Dense, Flatten, GlobalAveragePooling2D\n",
    "\n",
    "my_new_model = Sequential()\n",
    "\n",
    "my_new_model.add(ResNet50(include_top=False, pooling='avg', weights='imagenet'))\n",
    "\n",
    "my_new_model.add(Dense(num_classes, activation='softmax'))\n",
    "\n",
    "# Say not to train first layer (ResNet) model. It is already trained\n",
    "my_new_model.layers[0].trainable = False\n",
    "\n",
    "my_new_model.compile(optimizer='sgd', loss='categorical_crossentropy', metrics=['accuracy'])\n",
    "\n",
    "from tensorflow.keras import layers\n",
    "\n",
    "from tensorflow.keras.optimizers import SGD\n",
    "\n",
    "x = layers.Dropout(0.5)(my_new_model.output)\n",
    "\n",
    "x = layers.Flatten()(x)\n",
    "\n",
    "x = layers.Dropout(0.5)(x)\n",
    "\n",
    "x = layers.Dense(128, activation='relu', kernel_initializer='he_uniform')(x)\n",
    "\n",
    "x = layers.Dense(1, activation='sigmoid')(x)\n",
    "\n",
    "opt = SGD(lr=0.001, momentum=0.9)\n",
    "\n",
    "my_new_model.compile(loss='binary_crossentropy', optimizer=opt, metrics=[\"acc\"])\n",
    "\n",
    "my_new_model.summary()\n"
   ]
  },
  {
   "cell_type": "markdown",
   "id": "9d556be5",
   "metadata": {},
   "source": [
    "Generating the dataset"
   ]
  },
  {
   "cell_type": "code",
   "execution_count": 3,
   "id": "a14a2504",
   "metadata": {},
   "outputs": [
    {
     "ename": "ModuleNotFoundError",
     "evalue": "No module named 'keras.applications.resnet50'",
     "output_type": "error",
     "traceback": [
      "\u001b[1;31m---------------------------------------------------------------------------\u001b[0m",
      "\u001b[1;31mModuleNotFoundError\u001b[0m                       Traceback (most recent call last)",
      "\u001b[1;32m~\\AppData\\Local\\Temp/ipykernel_15820/617884899.py\u001b[0m in \u001b[0;36m<module>\u001b[1;34m\u001b[0m\n\u001b[1;32m----> 1\u001b[1;33m \u001b[1;32mfrom\u001b[0m \u001b[0mkeras\u001b[0m\u001b[1;33m.\u001b[0m\u001b[0mapplications\u001b[0m\u001b[1;33m.\u001b[0m\u001b[0mresnet50\u001b[0m \u001b[1;32mimport\u001b[0m \u001b[0mpreprocess_input\u001b[0m\u001b[1;33m\u001b[0m\u001b[1;33m\u001b[0m\u001b[0m\n\u001b[0m\u001b[0;32m      2\u001b[0m \u001b[1;33m\u001b[0m\u001b[0m\n\u001b[0;32m      3\u001b[0m \u001b[1;32mfrom\u001b[0m \u001b[0mkeras\u001b[0m\u001b[1;33m.\u001b[0m\u001b[0mpreprocessing\u001b[0m\u001b[1;33m.\u001b[0m\u001b[0mimage\u001b[0m \u001b[1;32mimport\u001b[0m \u001b[0mImageDataGenerator\u001b[0m\u001b[1;33m\u001b[0m\u001b[1;33m\u001b[0m\u001b[0m\n\u001b[0;32m      4\u001b[0m \u001b[1;33m\u001b[0m\u001b[0m\n\u001b[0;32m      5\u001b[0m \u001b[0mimage_size\u001b[0m \u001b[1;33m=\u001b[0m \u001b[0mIMAGE_RESIZE\u001b[0m\u001b[1;33m\u001b[0m\u001b[1;33m\u001b[0m\u001b[0m\n",
      "\u001b[1;31mModuleNotFoundError\u001b[0m: No module named 'keras.applications.resnet50'"
     ]
    }
   ],
   "source": [
    "from keras.applications.resnet50 import preprocess_input\n",
    "\n",
    "from keras.preprocessing.image import ImageDataGenerator\n",
    "\n",
    "image_size = IMAGE_RESIZE\n",
    "\n",
    "# preprocessing_function is applied on each image but only after re-sizing & augmentation (resize => augment => pre-process)\n",
    "\n",
    "# Each of the keras.application.resnet* preprocess_input MOSTLY mean BATCH NORMALIZATION (applied on each batch) stabilize the in\n",
    "#puts to nonlinear activation functions\n",
    "\n",
    "# Batch Normalization helps in faster convergence\n",
    "\n",
    "data_generator = ImageDataGenerator(preprocessing_function=preprocess_input)\n",
    "\n",
    "# flow_From_directory generates batches of augmented data (where augmentation can be color conversion, etc)\n",
    "\n",
    "# Both train & valid folders must have NUM_CLASSES sub-folders\n",
    "\n",
    "train_generator = data_generator.flow_from_directory(\n",
    "\n",
    "'C:\\Jahnavi\\RA Project\\Prj\\SEC1\\TRAIN',\n",
    "\n",
    "target_size=(image_size, image_size),\n",
    "\n",
    "batch_size=BATCH_SIZE_TRAINING,\n",
    "\n",
    "class_mode='categorical')\n",
    "\n",
    "validation_generator = data_generator.flow_from_directory(\n",
    "\n",
    "'C:\\Jahnavi\\RA Project\\Prj\\SEC1\\TEST',\n",
    "\n",
    "target_size=(image_size, image_size),\n",
    "\n",
    "batch_size=BATCH_SIZE_VALIDATION,\n",
    "\n",
    "class_mode='categorical')"
   ]
  },
  {
   "cell_type": "markdown",
   "id": "1af17843",
   "metadata": {},
   "source": [
    "Training the model"
   ]
  },
  {
   "cell_type": "code",
   "execution_count": null,
   "id": "0ab3eefe",
   "metadata": {},
   "outputs": [
    {
     "name": "stdout",
     "output_type": "stream",
     "text": [
      "WARNING:tensorflow:From C:\\Users\\jahna\\AppData\\Local\\Temp/ipykernel_23488/2325150928.py:13: Model.fit_generator (from tensorflow.python.keras.engine.training) is deprecated and will be removed in a future version.\n",
      "Instructions for updating:\n",
      "Please use Model.fit, which supports generators.\n"
     ]
    },
    {
     "name": "stderr",
     "output_type": "stream",
     "text": [
      "ERROR:root:Internal Python error in the inspect module.\n",
      "Below is the traceback from this internal error.\n",
      "\n",
      "ERROR:root:Internal Python error in the inspect module.\n",
      "Below is the traceback from this internal error.\n",
      "\n",
      "ERROR:root:Internal Python error in the inspect module.\n",
      "Below is the traceback from this internal error.\n",
      "\n"
     ]
    },
    {
     "name": "stdout",
     "output_type": "stream",
     "text": [
      "Traceback (most recent call last):\n",
      "  File \"C:\\Users\\jahna\\anaconda3\\envs\\keras_env\\lib\\site-packages\\IPython\\core\\interactiveshell.py\", line 3457, in run_code\n",
      "    exec(code_obj, self.user_global_ns, self.user_ns)\n",
      "  File \"C:\\Users\\jahna\\AppData\\Local\\Temp/ipykernel_23488/2325150928.py\", line 13, in <module>\n",
      "    validation_data=validation_generator)\n",
      "  File \"C:\\Users\\jahna\\anaconda3\\envs\\keras_env\\lib\\site-packages\\tensorflow_core\\python\\util\\deprecation.py\", line 324, in new_func\n",
      "    return func(*args, **kwargs)\n",
      "  File \"C:\\Users\\jahna\\anaconda3\\envs\\keras_env\\lib\\site-packages\\tensorflow_core\\python\\keras\\engine\\training.py\", line 1306, in fit_generator\n",
      "    initial_epoch=initial_epoch)\n",
      "  File \"C:\\Users\\jahna\\anaconda3\\envs\\keras_env\\lib\\site-packages\\tensorflow_core\\python\\keras\\engine\\training.py\", line 819, in fit\n",
      "    use_multiprocessing=use_multiprocessing)\n",
      "  File \"C:\\Users\\jahna\\anaconda3\\envs\\keras_env\\lib\\site-packages\\tensorflow_core\\python\\keras\\engine\\training_v2.py\", line 235, in fit\n",
      "    use_multiprocessing=use_multiprocessing)\n",
      "  File \"C:\\Users\\jahna\\anaconda3\\envs\\keras_env\\lib\\site-packages\\tensorflow_core\\python\\keras\\engine\\training_v2.py\", line 593, in _process_training_inputs\n",
      "    use_multiprocessing=use_multiprocessing)\n",
      "  File \"C:\\Users\\jahna\\anaconda3\\envs\\keras_env\\lib\\site-packages\\tensorflow_core\\python\\keras\\engine\\training_v2.py\", line 706, in _process_inputs\n",
      "    use_multiprocessing=use_multiprocessing)\n",
      "  File \"C:\\Users\\jahna\\anaconda3\\envs\\keras_env\\lib\\site-packages\\tensorflow_core\\python\\keras\\engine\\data_adapter.py\", line 952, in __init__\n",
      "    **kwargs)\n",
      "  File \"C:\\Users\\jahna\\anaconda3\\envs\\keras_env\\lib\\site-packages\\tensorflow_core\\python\\keras\\engine\\data_adapter.py\", line 747, in __init__\n",
      "    peek, x = self._peek_and_restore(x)\n",
      "  File \"C:\\Users\\jahna\\anaconda3\\envs\\keras_env\\lib\\site-packages\\tensorflow_core\\python\\keras\\engine\\data_adapter.py\", line 956, in _peek_and_restore\n",
      "    return x[0], x\n",
      "  File \"C:\\Users\\jahna\\anaconda3\\envs\\keras_env\\lib\\site-packages\\keras_preprocessing\\image\\iterator.py\", line 65, in __getitem__\n",
      "    return self._get_batches_of_transformed_samples(index_array)\n",
      "  File \"C:\\Users\\jahna\\anaconda3\\envs\\keras_env\\lib\\site-packages\\keras_preprocessing\\image\\iterator.py\", line 230, in _get_batches_of_transformed_samples\n",
      "    interpolation=self.interpolation)\n",
      "  File \"C:\\Users\\jahna\\anaconda3\\envs\\keras_env\\lib\\site-packages\\keras_preprocessing\\image\\utils.py\", line 108, in load_img\n",
      "    raise ImportError('Could not import PIL.Image. '\n",
      "ImportError: Could not import PIL.Image. The use of `load_img` requires PIL.\n",
      "\n",
      "During handling of the above exception, another exception occurred:\n",
      "\n",
      "Traceback (most recent call last):\n",
      "  File \"C:\\Users\\jahna\\anaconda3\\envs\\keras_env\\lib\\site-packages\\IPython\\core\\interactiveshell.py\", line 2077, in showtraceback\n",
      "    stb = value._render_traceback_()\n",
      "AttributeError: 'ImportError' object has no attribute '_render_traceback_'\n",
      "\n",
      "During handling of the above exception, another exception occurred:\n",
      "\n",
      "Traceback (most recent call last):\n",
      "  File \"C:\\Users\\jahna\\anaconda3\\envs\\keras_env\\lib\\site-packages\\IPython\\core\\ultratb.py\", line 1101, in get_records\n",
      "    return _fixed_getinnerframes(etb, number_of_lines_of_context, tb_offset)\n",
      "  File \"C:\\Users\\jahna\\anaconda3\\envs\\keras_env\\lib\\site-packages\\IPython\\core\\ultratb.py\", line 248, in wrapped\n",
      "    return f(*args, **kwargs)\n",
      "  File \"C:\\Users\\jahna\\anaconda3\\envs\\keras_env\\lib\\site-packages\\IPython\\core\\ultratb.py\", line 281, in _fixed_getinnerframes\n",
      "    records = fix_frame_records_filenames(inspect.getinnerframes(etb, context))\n",
      "  File \"C:\\Users\\jahna\\anaconda3\\envs\\keras_env\\lib\\inspect.py\", line 1502, in getinnerframes\n",
      "    frameinfo = (tb.tb_frame,) + getframeinfo(tb, context)\n",
      "  File \"C:\\Users\\jahna\\anaconda3\\envs\\keras_env\\lib\\inspect.py\", line 1460, in getframeinfo\n",
      "    filename = getsourcefile(frame) or getfile(frame)\n",
      "  File \"C:\\Users\\jahna\\anaconda3\\envs\\keras_env\\lib\\inspect.py\", line 696, in getsourcefile\n",
      "    if getattr(getmodule(object, filename), '__loader__', None) is not None:\n",
      "  File \"C:\\Users\\jahna\\anaconda3\\envs\\keras_env\\lib\\inspect.py\", line 733, in getmodule\n",
      "    if ismodule(module) and hasattr(module, '__file__'):\n",
      "  File \"C:\\Users\\jahna\\anaconda3\\envs\\keras_env\\lib\\site-packages\\tensorflow\\__init__.py\", line 50, in __getattr__\n",
      "    module = self._load()\n",
      "  File \"C:\\Users\\jahna\\anaconda3\\envs\\keras_env\\lib\\site-packages\\tensorflow\\__init__.py\", line 44, in _load\n",
      "    module = _importlib.import_module(self.__name__)\n",
      "  File \"C:\\Users\\jahna\\anaconda3\\envs\\keras_env\\lib\\importlib\\__init__.py\", line 127, in import_module\n",
      "    return _bootstrap._gcd_import(name[level:], package, level)\n",
      "  File \"<frozen importlib._bootstrap>\", line 1006, in _gcd_import\n",
      "  File \"<frozen importlib._bootstrap>\", line 983, in _find_and_load\n",
      "  File \"<frozen importlib._bootstrap>\", line 965, in _find_and_load_unlocked\n",
      "ModuleNotFoundError: No module named 'tensorflow_core.estimator'\n",
      "Traceback (most recent call last):\n",
      "  File \"C:\\Users\\jahna\\anaconda3\\envs\\keras_env\\lib\\site-packages\\IPython\\core\\interactiveshell.py\", line 3457, in run_code\n",
      "    exec(code_obj, self.user_global_ns, self.user_ns)\n",
      "  File \"C:\\Users\\jahna\\AppData\\Local\\Temp/ipykernel_23488/2325150928.py\", line 13, in <module>\n",
      "    validation_data=validation_generator)\n",
      "  File \"C:\\Users\\jahna\\anaconda3\\envs\\keras_env\\lib\\site-packages\\tensorflow_core\\python\\util\\deprecation.py\", line 324, in new_func\n",
      "    return func(*args, **kwargs)\n",
      "  File \"C:\\Users\\jahna\\anaconda3\\envs\\keras_env\\lib\\site-packages\\tensorflow_core\\python\\keras\\engine\\training.py\", line 1306, in fit_generator\n",
      "    initial_epoch=initial_epoch)\n",
      "  File \"C:\\Users\\jahna\\anaconda3\\envs\\keras_env\\lib\\site-packages\\tensorflow_core\\python\\keras\\engine\\training.py\", line 819, in fit\n",
      "    use_multiprocessing=use_multiprocessing)\n",
      "  File \"C:\\Users\\jahna\\anaconda3\\envs\\keras_env\\lib\\site-packages\\tensorflow_core\\python\\keras\\engine\\training_v2.py\", line 235, in fit\n",
      "    use_multiprocessing=use_multiprocessing)\n",
      "  File \"C:\\Users\\jahna\\anaconda3\\envs\\keras_env\\lib\\site-packages\\tensorflow_core\\python\\keras\\engine\\training_v2.py\", line 593, in _process_training_inputs\n",
      "    use_multiprocessing=use_multiprocessing)\n",
      "  File \"C:\\Users\\jahna\\anaconda3\\envs\\keras_env\\lib\\site-packages\\tensorflow_core\\python\\keras\\engine\\training_v2.py\", line 706, in _process_inputs\n",
      "    use_multiprocessing=use_multiprocessing)\n",
      "  File \"C:\\Users\\jahna\\anaconda3\\envs\\keras_env\\lib\\site-packages\\tensorflow_core\\python\\keras\\engine\\data_adapter.py\", line 952, in __init__\n",
      "    **kwargs)\n",
      "  File \"C:\\Users\\jahna\\anaconda3\\envs\\keras_env\\lib\\site-packages\\tensorflow_core\\python\\keras\\engine\\data_adapter.py\", line 747, in __init__\n",
      "    peek, x = self._peek_and_restore(x)\n",
      "  File \"C:\\Users\\jahna\\anaconda3\\envs\\keras_env\\lib\\site-packages\\tensorflow_core\\python\\keras\\engine\\data_adapter.py\", line 956, in _peek_and_restore\n",
      "    return x[0], x\n",
      "  File \"C:\\Users\\jahna\\anaconda3\\envs\\keras_env\\lib\\site-packages\\keras_preprocessing\\image\\iterator.py\", line 65, in __getitem__\n",
      "    return self._get_batches_of_transformed_samples(index_array)\n",
      "  File \"C:\\Users\\jahna\\anaconda3\\envs\\keras_env\\lib\\site-packages\\keras_preprocessing\\image\\iterator.py\", line 230, in _get_batches_of_transformed_samples\n",
      "    interpolation=self.interpolation)\n",
      "  File \"C:\\Users\\jahna\\anaconda3\\envs\\keras_env\\lib\\site-packages\\keras_preprocessing\\image\\utils.py\", line 108, in load_img\n",
      "    raise ImportError('Could not import PIL.Image. '\n",
      "ImportError: Could not import PIL.Image. The use of `load_img` requires PIL.\n",
      "\n",
      "During handling of the above exception, another exception occurred:\n",
      "\n",
      "Traceback (most recent call last):\n",
      "  File \"C:\\Users\\jahna\\anaconda3\\envs\\keras_env\\lib\\site-packages\\IPython\\core\\interactiveshell.py\", line 2077, in showtraceback\n",
      "    stb = value._render_traceback_()\n",
      "AttributeError: 'ImportError' object has no attribute '_render_traceback_'\n",
      "\n",
      "During handling of the above exception, another exception occurred:\n",
      "\n",
      "Traceback (most recent call last):\n",
      "  File \"C:\\Users\\jahna\\anaconda3\\envs\\keras_env\\lib\\site-packages\\IPython\\core\\interactiveshell.py\", line 3377, in run_ast_nodes\n",
      "    if (await self.run_code(code, result,  async_=asy)):\n",
      "  File \"C:\\Users\\jahna\\anaconda3\\envs\\keras_env\\lib\\site-packages\\IPython\\core\\interactiveshell.py\", line 3474, in run_code\n",
      "    self.showtraceback(running_compiled_code=True)\n",
      "  File \"C:\\Users\\jahna\\anaconda3\\envs\\keras_env\\lib\\site-packages\\IPython\\core\\interactiveshell.py\", line 2080, in showtraceback\n",
      "    value, tb, tb_offset=tb_offset)\n",
      "  File \"C:\\Users\\jahna\\anaconda3\\envs\\keras_env\\lib\\site-packages\\IPython\\core\\ultratb.py\", line 1368, in structured_traceback\n",
      "    self, etype, value, tb, tb_offset, number_of_lines_of_context)\n",
      "  File \"C:\\Users\\jahna\\anaconda3\\envs\\keras_env\\lib\\site-packages\\IPython\\core\\ultratb.py\", line 1268, in structured_traceback\n",
      "    self, etype, value, tb, tb_offset, number_of_lines_of_context\n",
      "  File \"C:\\Users\\jahna\\anaconda3\\envs\\keras_env\\lib\\site-packages\\IPython\\core\\ultratb.py\", line 1125, in structured_traceback\n",
      "    tb_offset)\n",
      "  File \"C:\\Users\\jahna\\anaconda3\\envs\\keras_env\\lib\\site-packages\\IPython\\core\\ultratb.py\", line 1082, in format_exception_as_a_whole\n",
      "    last_unique, recursion_repeat = find_recursion(orig_etype, evalue, records)\n",
      "  File \"C:\\Users\\jahna\\anaconda3\\envs\\keras_env\\lib\\site-packages\\IPython\\core\\ultratb.py\", line 382, in find_recursion\n",
      "    return len(records), 0\n",
      "TypeError: object of type 'NoneType' has no len()\n",
      "\n",
      "During handling of the above exception, another exception occurred:\n",
      "\n",
      "Traceback (most recent call last):\n",
      "  File \"C:\\Users\\jahna\\anaconda3\\envs\\keras_env\\lib\\site-packages\\IPython\\core\\interactiveshell.py\", line 2077, in showtraceback\n",
      "    stb = value._render_traceback_()\n",
      "AttributeError: 'TypeError' object has no attribute '_render_traceback_'\n",
      "\n",
      "During handling of the above exception, another exception occurred:\n",
      "\n",
      "Traceback (most recent call last):\n",
      "  File \"C:\\Users\\jahna\\anaconda3\\envs\\keras_env\\lib\\site-packages\\IPython\\core\\ultratb.py\", line 1101, in get_records\n",
      "    return _fixed_getinnerframes(etb, number_of_lines_of_context, tb_offset)\n",
      "  File \"C:\\Users\\jahna\\anaconda3\\envs\\keras_env\\lib\\site-packages\\IPython\\core\\ultratb.py\", line 248, in wrapped\n",
      "    return f(*args, **kwargs)\n",
      "  File \"C:\\Users\\jahna\\anaconda3\\envs\\keras_env\\lib\\site-packages\\IPython\\core\\ultratb.py\", line 281, in _fixed_getinnerframes\n",
      "    records = fix_frame_records_filenames(inspect.getinnerframes(etb, context))\n",
      "  File \"C:\\Users\\jahna\\anaconda3\\envs\\keras_env\\lib\\inspect.py\", line 1502, in getinnerframes\n",
      "    frameinfo = (tb.tb_frame,) + getframeinfo(tb, context)\n",
      "  File \"C:\\Users\\jahna\\anaconda3\\envs\\keras_env\\lib\\inspect.py\", line 1460, in getframeinfo\n",
      "    filename = getsourcefile(frame) or getfile(frame)\n",
      "  File \"C:\\Users\\jahna\\anaconda3\\envs\\keras_env\\lib\\inspect.py\", line 696, in getsourcefile\n",
      "    if getattr(getmodule(object, filename), '__loader__', None) is not None:\n",
      "  File \"C:\\Users\\jahna\\anaconda3\\envs\\keras_env\\lib\\inspect.py\", line 733, in getmodule\n",
      "    if ismodule(module) and hasattr(module, '__file__'):\n",
      "  File \"C:\\Users\\jahna\\anaconda3\\envs\\keras_env\\lib\\site-packages\\tensorflow\\__init__.py\", line 50, in __getattr__\n",
      "    module = self._load()\n",
      "  File \"C:\\Users\\jahna\\anaconda3\\envs\\keras_env\\lib\\site-packages\\tensorflow\\__init__.py\", line 44, in _load\n",
      "    module = _importlib.import_module(self.__name__)\n",
      "  File \"C:\\Users\\jahna\\anaconda3\\envs\\keras_env\\lib\\importlib\\__init__.py\", line 127, in import_module\n",
      "    return _bootstrap._gcd_import(name[level:], package, level)\n",
      "  File \"<frozen importlib._bootstrap>\", line 1006, in _gcd_import\n",
      "  File \"<frozen importlib._bootstrap>\", line 983, in _find_and_load\n",
      "  File \"<frozen importlib._bootstrap>\", line 965, in _find_and_load_unlocked\n",
      "ModuleNotFoundError: No module named 'tensorflow_core.estimator'\n",
      "Traceback (most recent call last):\n",
      "  File \"C:\\Users\\jahna\\anaconda3\\envs\\keras_env\\lib\\site-packages\\IPython\\core\\interactiveshell.py\", line 3457, in run_code\n",
      "    exec(code_obj, self.user_global_ns, self.user_ns)\n",
      "  File \"C:\\Users\\jahna\\AppData\\Local\\Temp/ipykernel_23488/2325150928.py\", line 13, in <module>\n",
      "    validation_data=validation_generator)\n",
      "  File \"C:\\Users\\jahna\\anaconda3\\envs\\keras_env\\lib\\site-packages\\tensorflow_core\\python\\util\\deprecation.py\", line 324, in new_func\n",
      "    return func(*args, **kwargs)\n",
      "  File \"C:\\Users\\jahna\\anaconda3\\envs\\keras_env\\lib\\site-packages\\tensorflow_core\\python\\keras\\engine\\training.py\", line 1306, in fit_generator\n",
      "    initial_epoch=initial_epoch)\n",
      "  File \"C:\\Users\\jahna\\anaconda3\\envs\\keras_env\\lib\\site-packages\\tensorflow_core\\python\\keras\\engine\\training.py\", line 819, in fit\n",
      "    use_multiprocessing=use_multiprocessing)\n",
      "  File \"C:\\Users\\jahna\\anaconda3\\envs\\keras_env\\lib\\site-packages\\tensorflow_core\\python\\keras\\engine\\training_v2.py\", line 235, in fit\n",
      "    use_multiprocessing=use_multiprocessing)\n",
      "  File \"C:\\Users\\jahna\\anaconda3\\envs\\keras_env\\lib\\site-packages\\tensorflow_core\\python\\keras\\engine\\training_v2.py\", line 593, in _process_training_inputs\n",
      "    use_multiprocessing=use_multiprocessing)\n",
      "  File \"C:\\Users\\jahna\\anaconda3\\envs\\keras_env\\lib\\site-packages\\tensorflow_core\\python\\keras\\engine\\training_v2.py\", line 706, in _process_inputs\n",
      "    use_multiprocessing=use_multiprocessing)\n",
      "  File \"C:\\Users\\jahna\\anaconda3\\envs\\keras_env\\lib\\site-packages\\tensorflow_core\\python\\keras\\engine\\data_adapter.py\", line 952, in __init__\n",
      "    **kwargs)\n",
      "  File \"C:\\Users\\jahna\\anaconda3\\envs\\keras_env\\lib\\site-packages\\tensorflow_core\\python\\keras\\engine\\data_adapter.py\", line 747, in __init__\n",
      "    peek, x = self._peek_and_restore(x)\n",
      "  File \"C:\\Users\\jahna\\anaconda3\\envs\\keras_env\\lib\\site-packages\\tensorflow_core\\python\\keras\\engine\\data_adapter.py\", line 956, in _peek_and_restore\n",
      "    return x[0], x\n",
      "  File \"C:\\Users\\jahna\\anaconda3\\envs\\keras_env\\lib\\site-packages\\keras_preprocessing\\image\\iterator.py\", line 65, in __getitem__\n",
      "    return self._get_batches_of_transformed_samples(index_array)\n",
      "  File \"C:\\Users\\jahna\\anaconda3\\envs\\keras_env\\lib\\site-packages\\keras_preprocessing\\image\\iterator.py\", line 230, in _get_batches_of_transformed_samples\n",
      "    interpolation=self.interpolation)\n",
      "  File \"C:\\Users\\jahna\\anaconda3\\envs\\keras_env\\lib\\site-packages\\keras_preprocessing\\image\\utils.py\", line 108, in load_img\n",
      "    raise ImportError('Could not import PIL.Image. '\n",
      "ImportError: Could not import PIL.Image. The use of `load_img` requires PIL.\n",
      "\n",
      "During handling of the above exception, another exception occurred:\n",
      "\n",
      "Traceback (most recent call last):\n",
      "  File \"C:\\Users\\jahna\\anaconda3\\envs\\keras_env\\lib\\site-packages\\IPython\\core\\interactiveshell.py\", line 2077, in showtraceback\n",
      "    stb = value._render_traceback_()\n",
      "AttributeError: 'ImportError' object has no attribute '_render_traceback_'\n",
      "\n",
      "During handling of the above exception, another exception occurred:\n",
      "\n",
      "Traceback (most recent call last):\n",
      "  File \"C:\\Users\\jahna\\anaconda3\\envs\\keras_env\\lib\\site-packages\\IPython\\core\\interactiveshell.py\", line 3377, in run_ast_nodes\n",
      "    if (await self.run_code(code, result,  async_=asy)):\n",
      "  File \"C:\\Users\\jahna\\anaconda3\\envs\\keras_env\\lib\\site-packages\\IPython\\core\\interactiveshell.py\", line 3474, in run_code\n",
      "    self.showtraceback(running_compiled_code=True)\n",
      "  File \"C:\\Users\\jahna\\anaconda3\\envs\\keras_env\\lib\\site-packages\\IPython\\core\\interactiveshell.py\", line 2080, in showtraceback\n",
      "    value, tb, tb_offset=tb_offset)\n",
      "  File \"C:\\Users\\jahna\\anaconda3\\envs\\keras_env\\lib\\site-packages\\IPython\\core\\ultratb.py\", line 1368, in structured_traceback\n",
      "    self, etype, value, tb, tb_offset, number_of_lines_of_context)\n",
      "  File \"C:\\Users\\jahna\\anaconda3\\envs\\keras_env\\lib\\site-packages\\IPython\\core\\ultratb.py\", line 1268, in structured_traceback\n",
      "    self, etype, value, tb, tb_offset, number_of_lines_of_context\n",
      "  File \"C:\\Users\\jahna\\anaconda3\\envs\\keras_env\\lib\\site-packages\\IPython\\core\\ultratb.py\", line 1125, in structured_traceback\n",
      "    tb_offset)\n",
      "  File \"C:\\Users\\jahna\\anaconda3\\envs\\keras_env\\lib\\site-packages\\IPython\\core\\ultratb.py\", line 1082, in format_exception_as_a_whole\n",
      "    last_unique, recursion_repeat = find_recursion(orig_etype, evalue, records)\n",
      "  File \"C:\\Users\\jahna\\anaconda3\\envs\\keras_env\\lib\\site-packages\\IPython\\core\\ultratb.py\", line 382, in find_recursion\n",
      "    return len(records), 0\n",
      "TypeError: object of type 'NoneType' has no len()\n",
      "\n",
      "During handling of the above exception, another exception occurred:\n",
      "\n",
      "Traceback (most recent call last):\n",
      "  File \"C:\\Users\\jahna\\anaconda3\\envs\\keras_env\\lib\\site-packages\\IPython\\core\\interactiveshell.py\", line 2077, in showtraceback\n",
      "    stb = value._render_traceback_()\n",
      "AttributeError: 'TypeError' object has no attribute '_render_traceback_'\n",
      "\n",
      "During handling of the above exception, another exception occurred:\n",
      "\n",
      "Traceback (most recent call last):\n",
      "  File \"C:\\Users\\jahna\\anaconda3\\envs\\keras_env\\lib\\site-packages\\IPython\\core\\interactiveshell.py\", line 2960, in _run_cell\n",
      "    return runner(coro)\n",
      "  File \"C:\\Users\\jahna\\anaconda3\\envs\\keras_env\\lib\\site-packages\\IPython\\core\\async_helpers.py\", line 78, in _pseudo_sync_runner\n",
      "    coro.send(None)\n",
      "  File \"C:\\Users\\jahna\\anaconda3\\envs\\keras_env\\lib\\site-packages\\IPython\\core\\interactiveshell.py\", line 3186, in run_cell_async\n",
      "    interactivity=interactivity, compiler=compiler, result=result)\n",
      "  File \"C:\\Users\\jahna\\anaconda3\\envs\\keras_env\\lib\\site-packages\\IPython\\core\\interactiveshell.py\", line 3396, in run_ast_nodes\n",
      "    self.showtraceback()\n",
      "  File \"C:\\Users\\jahna\\anaconda3\\envs\\keras_env\\lib\\site-packages\\IPython\\core\\interactiveshell.py\", line 2080, in showtraceback\n",
      "    value, tb, tb_offset=tb_offset)\n",
      "  File \"C:\\Users\\jahna\\anaconda3\\envs\\keras_env\\lib\\site-packages\\IPython\\core\\ultratb.py\", line 1368, in structured_traceback\n",
      "    self, etype, value, tb, tb_offset, number_of_lines_of_context)\n",
      "  File \"C:\\Users\\jahna\\anaconda3\\envs\\keras_env\\lib\\site-packages\\IPython\\core\\ultratb.py\", line 1268, in structured_traceback\n",
      "    self, etype, value, tb, tb_offset, number_of_lines_of_context\n",
      "  File \"C:\\Users\\jahna\\anaconda3\\envs\\keras_env\\lib\\site-packages\\IPython\\core\\ultratb.py\", line 1143, in structured_traceback\n",
      "    chained_exceptions_tb_offset)\n",
      "  File \"C:\\Users\\jahna\\anaconda3\\envs\\keras_env\\lib\\site-packages\\IPython\\core\\ultratb.py\", line 1082, in format_exception_as_a_whole\n",
      "    last_unique, recursion_repeat = find_recursion(orig_etype, evalue, records)\n",
      "  File \"C:\\Users\\jahna\\anaconda3\\envs\\keras_env\\lib\\site-packages\\IPython\\core\\ultratb.py\", line 382, in find_recursion\n",
      "    return len(records), 0\n",
      "TypeError: object of type 'NoneType' has no len()\n",
      "\n",
      "During handling of the above exception, another exception occurred:\n",
      "\n",
      "Traceback (most recent call last):\n",
      "  File \"C:\\Users\\jahna\\anaconda3\\envs\\keras_env\\lib\\site-packages\\IPython\\core\\interactiveshell.py\", line 2077, in showtraceback\n",
      "    stb = value._render_traceback_()\n",
      "AttributeError: 'TypeError' object has no attribute '_render_traceback_'\n",
      "\n",
      "During handling of the above exception, another exception occurred:\n",
      "\n",
      "Traceback (most recent call last):\n",
      "  File \"C:\\Users\\jahna\\anaconda3\\envs\\keras_env\\lib\\site-packages\\IPython\\core\\ultratb.py\", line 1101, in get_records\n",
      "    return _fixed_getinnerframes(etb, number_of_lines_of_context, tb_offset)\n",
      "  File \"C:\\Users\\jahna\\anaconda3\\envs\\keras_env\\lib\\site-packages\\IPython\\core\\ultratb.py\", line 248, in wrapped\n",
      "    return f(*args, **kwargs)\n",
      "  File \"C:\\Users\\jahna\\anaconda3\\envs\\keras_env\\lib\\site-packages\\IPython\\core\\ultratb.py\", line 281, in _fixed_getinnerframes\n",
      "    records = fix_frame_records_filenames(inspect.getinnerframes(etb, context))\n",
      "  File \"C:\\Users\\jahna\\anaconda3\\envs\\keras_env\\lib\\inspect.py\", line 1502, in getinnerframes\n",
      "    frameinfo = (tb.tb_frame,) + getframeinfo(tb, context)\n",
      "  File \"C:\\Users\\jahna\\anaconda3\\envs\\keras_env\\lib\\inspect.py\", line 1460, in getframeinfo\n",
      "    filename = getsourcefile(frame) or getfile(frame)\n",
      "  File \"C:\\Users\\jahna\\anaconda3\\envs\\keras_env\\lib\\inspect.py\", line 696, in getsourcefile\n",
      "    if getattr(getmodule(object, filename), '__loader__', None) is not None:\n",
      "  File \"C:\\Users\\jahna\\anaconda3\\envs\\keras_env\\lib\\inspect.py\", line 733, in getmodule\n",
      "    if ismodule(module) and hasattr(module, '__file__'):\n",
      "  File \"C:\\Users\\jahna\\anaconda3\\envs\\keras_env\\lib\\site-packages\\tensorflow\\__init__.py\", line 50, in __getattr__\n",
      "    module = self._load()\n",
      "  File \"C:\\Users\\jahna\\anaconda3\\envs\\keras_env\\lib\\site-packages\\tensorflow\\__init__.py\", line 44, in _load\n",
      "    module = _importlib.import_module(self.__name__)\n",
      "  File \"C:\\Users\\jahna\\anaconda3\\envs\\keras_env\\lib\\importlib\\__init__.py\", line 127, in import_module\n",
      "    return _bootstrap._gcd_import(name[level:], package, level)\n",
      "  File \"<frozen importlib._bootstrap>\", line 1006, in _gcd_import\n",
      "  File \"<frozen importlib._bootstrap>\", line 983, in _find_and_load\n",
      "  File \"<frozen importlib._bootstrap>\", line 965, in _find_and_load_unlocked\n",
      "ModuleNotFoundError: No module named 'tensorflow_core.estimator'\n"
     ]
    }
   ],
   "source": [
    "(BATCH_SIZE_TRAINING, len(train_generator), BATCH_SIZE_VALIDATION, len(validation_generator))\n",
    "\n",
    "my_new_model.fit_generator(\n",
    "\n",
    "train_generator,\n",
    "\n",
    "epochs=5,\n",
    "\n",
    "steps_per_epoch=len(train_generator),\n",
    "\n",
    "validation_steps=len(validation_generator),\n",
    "\n",
    "validation_data=validation_generator)"
   ]
  }
 ],
 "metadata": {
  "kernelspec": {
   "display_name": "Python 3 (ipykernel)",
   "language": "python",
   "name": "python3"
  },
  "language_info": {
   "codemirror_mode": {
    "name": "ipython",
    "version": 3
   },
   "file_extension": ".py",
   "mimetype": "text/x-python",
   "name": "python",
   "nbconvert_exporter": "python",
   "pygments_lexer": "ipython3",
   "version": "3.9.7"
  }
 },
 "nbformat": 4,
 "nbformat_minor": 5
}
